# Ответы на контрольные вопросы
1) Данный код написан правильно, допускается писать блок `finally` после блока `try`, он выполнится в любом случае, независимо от того, возникло исключение или нет.
2)  Этот блок перехватывает все исключения, которые являются экземплярами класса `Exception` или его подклассов, включая проверяемые и непроверяемые исключения. Однако, использование такого обработчика может быть проблематичным, потому что он перехватывает все исключения, включая те, которые должны быть обработаны на более конкретных уровнях, и мы не имеем конкретной информации о типе выброшенного исключения, что затрудяет его корректную обработку.
3) В данном коде есть ошибка, он не скомпилируется. Дело в том, что порядок перехвата исключений должен быть таким, чтобы сначала перехватывались более конкретные исключения, а потом более общие. В данном случае, `ArithmeticException` является подклассом `Exception`, и обработчик `catch (Exception e)` перехватывает все исключения, включая `ArithmeticException`. Это означает, что второй блок `catch (ArithmeticException a)` никогда не будет достигнут, и компилятор выдает ошибку.
4) а - 3\
   б - 1\
   в - 4\
   г - 2